Traceback (most recent call last):
  File "/Users/peanutcookie/anaconda3/lib/python3.10/site-packages/jupyter_cache/executors/utils.py", line 58, in single_nb_execution
    executenb(
  File "/Users/peanutcookie/anaconda3/lib/python3.10/site-packages/nbclient/client.py", line 1204, in execute
    return NotebookClient(nb=nb, resources=resources, km=km, **kwargs).execute()
  File "/Users/peanutcookie/anaconda3/lib/python3.10/site-packages/nbclient/util.py", line 84, in wrapped
    return just_run(coro(*args, **kwargs))
  File "/Users/peanutcookie/anaconda3/lib/python3.10/site-packages/nbclient/util.py", line 62, in just_run
    return loop.run_until_complete(coro)
  File "/Users/peanutcookie/anaconda3/lib/python3.10/asyncio/base_events.py", line 649, in run_until_complete
    return future.result()
  File "/Users/peanutcookie/anaconda3/lib/python3.10/site-packages/nbclient/client.py", line 663, in async_execute
    await self.async_execute_cell(
  File "/Users/peanutcookie/anaconda3/lib/python3.10/site-packages/nbclient/client.py", line 965, in async_execute_cell
    await self._check_raise_for_error(cell, cell_index, exec_reply)
  File "/Users/peanutcookie/anaconda3/lib/python3.10/site-packages/nbclient/client.py", line 862, in _check_raise_for_error
    raise CellExecutionError.from_cell_and_msg(cell, exec_reply_content)
nbclient.exceptions.CellExecutionError: An error occurred while executing the following cell:
------------------
# Import pkl file
df = pd.read_pickle(os.path.join(path, '_database', 'orders_products_merged.pkl'))
------------------

[0;31m---------------------------------------------------------------------------[0m
[0;31mEOFError[0m                                  Traceback (most recent call last)
Cell [0;32mIn[3], line 2[0m
[1;32m      1[0m [38;5;66;03m# Import pkl file[39;00m
[0;32m----> 2[0m df [38;5;241m=[39m [43mpd[49m[38;5;241;43m.[39;49m[43mread_pickle[49m[43m([49m[43mos[49m[38;5;241;43m.[39;49m[43mpath[49m[38;5;241;43m.[39;49m[43mjoin[49m[43m([49m[43mpath[49m[43m,[49m[43m [49m[38;5;124;43m'[39;49m[38;5;124;43m_database[39;49m[38;5;124;43m'[39;49m[43m,[49m[43m [49m[38;5;124;43m'[39;49m[38;5;124;43morders_products_merged.pkl[39;49m[38;5;124;43m'[39;49m[43m)[49m[43m)[49m

File [0;32m~/anaconda3/lib/python3.10/site-packages/pandas/io/pickle.py:208[0m, in [0;36mread_pickle[0;34m(filepath_or_buffer, compression, storage_options)[0m
[1;32m    205[0m     [38;5;28;01mwith[39;00m warnings[38;5;241m.[39mcatch_warnings(record[38;5;241m=[39m[38;5;28;01mTrue[39;00m):
[1;32m    206[0m         [38;5;66;03m# We want to silence any warnings about, e.g. moved modules.[39;00m
[1;32m    207[0m         warnings[38;5;241m.[39msimplefilter([38;5;124m"[39m[38;5;124mignore[39m[38;5;124m"[39m, [38;5;167;01mWarning[39;00m)
[0;32m--> 208[0m         [38;5;28;01mreturn[39;00m [43mpickle[49m[38;5;241;43m.[39;49m[43mload[49m[43m([49m[43mhandles[49m[38;5;241;43m.[39;49m[43mhandle[49m[43m)[49m
[1;32m    209[0m [38;5;28;01mexcept[39;00m excs_to_catch:
[1;32m    210[0m     [38;5;66;03m# e.g.[39;00m
[1;32m    211[0m     [38;5;66;03m#  "No module named 'pandas.core.sparse.series'"[39;00m
[1;32m    212[0m     [38;5;66;03m#  "Can't get attribute '__nat_unpickle' on <module 'pandas._libs.tslib"[39;00m
[1;32m    213[0m     [38;5;28;01mreturn[39;00m pc[38;5;241m.[39mload(handles[38;5;241m.[39mhandle, encoding[38;5;241m=[39m[38;5;28;01mNone[39;00m)

[0;31mEOFError[0m: Ran out of input
EOFError: Ran out of input

